<?xml version="1.0"?>
<robot name="vnymous">

  <link name="base_footprint"/>

  <link name="base_link">
    <visual>
      <origin rpy="0 -0 1.5707" xyz="0 0.35 0"/>
      <geometry>
        <mesh filename="file:///home/abhiyaan-nuc/ar_ws/src/ar_sim/meshes/igvc/igvc_bot.dae" scale="0.001 0.001 0.001"/>
      </geometry>
    </visual>
    <collision>
      <origin rpy="0 -0 1.5707" xyz="0 0.35 0"/>
      <geometry>
        <mesh filename="file:///home/abhiyaan-nuc/ar_ws/src/ar_sim/meshes/igvc/igvc_bot.dae" scale="0.001 0.001 0.001"/>
      </geometry>   
    </collision>

    <inertial>
      <mass value="10"/>
      <inertia ixx="0.166667" ixy="0.0" ixz="0.0" iyy="0.166667" iyz="0.0" izz="0.166667"/>
    </inertial>
  </link>
    
  <link name="perpendicular">
    <visual>
      <origin rpy="0 0 0" xyz="0 0 0"/>
      <geometry>
        <box size="0.0001 0.00001 0.00001"/>
      </geometry>
    </visual>
        
    <collision>
      <origin rpy="0 0 0" xyz="0 0 0"/>
      <geometry>
        <box size="0.0001 0.00001 0.00001"/>
      </geometry>
    </collision>
        
    <inertial>
      <mass value="0"/>
      <inertia ixx="0.0" ixy="0.0" ixz="0.0" iyy="0.0" iyz="0.0" izz="0.0"/>
    </inertial>
  </link>

  <link name="zed_camera">
    <visual>
      <origin rpy="0 0 1.5707" xyz="-0.015 -0.005 0"/>
      <geometry>
        <mesh filename="file:///home/abhiyaan-nuc/ar_ws/src/ar_sim/meshes/igvc/zed2i.dae" scale="1 1 1"/>
      </geometry>
    </visual>  

    <collision>
      <origin rpy="0 0 1.5707" xyz="-0.015 -0.005 0"/>
      <geometry>
        <mesh filename="file:///home/abhiyaan-nuc/ar_ws/src/ar_sim/meshes/igvc/zed2i.dae"/>
      </geometry>
    </collision>
      
    <inertial>
      <mass value="0.5"/>
      <inertia ixx="0.166667" ixy="0.0" ixz="0.0" iyy="0.166667" iyz="0.0" izz="0.166667"/>
    </inertial>
  </link>

  <gazebo reference="zed_camera">
    <sensor name="zedcam" type="depth">
      <always_on>true</always_on>
      <update_rate>15</update_rate>
      <pose>0 0 0 0 0 0</pose>
      <camera name="zed_depth_camera">
        <horizontal_fov>1.46608</horizontal_fov>
        <image>
          <width>1920</width>
          <height>1080</height>
          <format>B8G8R8</format>
        </image>
        <clip>
          <near>0.05</near>
          <far>8</far>
        </clip>
      </camera>
            
      <plugin name="depthcam_driver" filename="libgazebo_ros_camera.so">
        <ros>
          <namespace>zed</namespace>
          <!-- <remapping>${name}/points:=depth/points</remapping> -->
        </ros>
        <camera_name>zed_node</camera_name>
        <frame_name>perpendicular</frame_name>
        <hack_baseline>0.07</hack_baseline>
        <min_depth>0.05</min_depth>
        <max_depth>8.0</max_depth>
      </plugin>
    </sensor>
  </gazebo>

  <link name="gps_link">
    <visual>
      <origin rpy="0 0 0" xyz="0 0 0"/>
      <geometry>
        <box size="0.13 0.13 0.07"/>
      </geometry>
    </visual>  

    <collision>
      <origin rpy="0 0 0" xyz="0 0 0"/>
      <geometry>
        <box size="0.13 0.13 0.07"/>
      </geometry>
    </collision>
      
    <inertial>
      <mass value="0.5"/>
      <inertia ixx="0.166667" ixy="0.0" ixz="0.0" iyy="0.166667" iyz="0.0" izz="0.166667"/>
    </inertial>
  </link>

  <gazebo reference="gps_link">
    <sensor name="gps_sensor" type="gps">
        <always_on>true</always_on>
        <update_rate>1.0</update_rate>
        
        <gps>
          <position_sensing>
            <horizontal>
              <noise type="gaussian">
                <mean>0.0</mean>
                <stddev>0.01</stddev>
              </noise>
            </horizontal>
            <vertical>
              <noise type="gaussian">
                <mean>0.0</mean>
                <stddev>0.01</stddev>
              </noise>
            </vertical>
          </position_sensing>
        </gps>

        <plugin name="gps_controller" filename="libgazebo_ros_gps_sensor.so">
            <ros>
                <!-- <namespace>/br</namespace> -->
                <remapping>~/out:=/gps/fix</remapping>
            </ros>
            <frame_name>gps_link</frame_name>
        </plugin>
    </sensor>
    <material>Gazebo/Red</material>
  </gazebo>

  <link name="imu_link">
    <visual>
      <origin rpy="0 0 0" xyz="0 0 0"/>
      <geometry>
        <box size="0.1 0.1 0.07"/>
      </geometry>
    </visual>  

    <collision>
      <origin rpy="0 0 0" xyz="0 0 0"/>
      <geometry>
        <box size="0.1 0.1 0.07"/>
      </geometry>
    </collision>
      
    <inertial>
      <mass value="0.2"/>
      <inertia ixx="0.166667" ixy="0.0" ixz="0.0" iyy="0.166667" iyz="0.0" izz="0.166667"/>
    </inertial>
  </link>

  <gazebo reference="imu_link">
    <sensor name="br_imu" type="imu">
        <always_on>true</always_on>
        <update_rate>100</update_rate>
        <imu>
          <angular_velocity>
            <x>
              <noise type="gaussian">
                <mean>0.0</mean>
                <stddev>2e-4</stddev>
              </noise>
            </x>
            <y>
              <noise type="gaussian">
                <mean>0.0</mean>
                <stddev>2e-4</stddev>
              </noise>
            </y>
            <z>
              <noise type="gaussian">
                <mean>0.0</mean>
                <stddev>2e-4</stddev>
              </noise>
            </z>
          </angular_velocity>
          <linear_acceleration>
            <x>
              <noise type="gaussian">
                <mean>0.0</mean>
                <stddev>1.7e-2</stddev>
              </noise>
            </x>
            <y>
              <noise type="gaussian">
                <mean>0.0</mean>
                <stddev>1.7e-2</stddev>
              </noise>
            </y>
            <z>
              <noise type="gaussian">
                <mean>0.0</mean>
                <stddev>1.7e-2</stddev>
              </noise>
            </z>
          </linear_acceleration>
        </imu>
        <plugin name="bytes_imu" filename="libgazebo_ros_imu_sensor.so">
            <ros>
                <namespace>imu</namespace>
                <remapping>~/out:=data</remapping>
            </ros>
            <initial_orientation_as_reference>false</initial_orientation_as_reference>
        </plugin>
    </sensor>
  </gazebo>

  <link name="wheel1">
    <visual>
      <geometry>
        <mesh filename="file:///home/abhiyaan-nuc/ar_ws/src/ar_sim/meshes/igvc/igvc_wheel.dae" scale="0.001 0.001 0.001"/>
      </geometry>
      <origin rpy ="0 0 0" xyz="0 0 0"/>
    </visual>

    <collision>
      <geometry>
        <cylinder radius="0.12" length="0.04"/>
      </geometry>
      <origin rpy ="1.5707 0 1.5707" xyz="-0.065 0 0"/>
    </collision>

    <inertial>
      <mass value="5"/>
      <inertia ixx="0.166667" ixy="0.0" ixz="0.0" iyy="0.166667" iyz="0.0" izz="0.166667"/>
    </inertial>
  </link>

  <link name="wheel2">
    <visual>
      <geometry>
        <mesh filename="file:///home/abhiyaan-nuc/ar_ws/src/ar_sim/meshes/igvc/igvc_wheel.dae" scale="0.001 0.001 0.001"/>
      </geometry>
    <origin rpy ="0 0 0" xyz="0 0 0"/>
    </visual>

    <collision>
      <geometry>
        <cylinder radius="0.12" length="0.04"/>
      </geometry>
      <origin rpy ="1.5707 0 1.5707" xyz="-0.065 0 0"/>
    </collision>

    <inertial>
      <mass value="5"/>
      <inertia ixx="0.166667" ixy="0.0" ixz="0.0" iyy="0.166667" iyz="0.0" izz="0.166667"/>
    </inertial>
  </link>

  <link name="castor_ball">
    <visual>
      <geometry>
        <sphere radius="0.05"/>
      </geometry>
      <origin rpy="0 0 0" xyz="0 0 0"/>
    </visual>

    <collision>
      <geometry>
        <sphere radius="0.05"/>
      </geometry>
      <origin rpy="0 0 0" xyz="0 0 0"/>
    </collision>

    <inertial>
      <mass value="3"/>
      <inertia ixx="0.166667" ixy="0.0" ixz="0.0" iyy="0.166667" iyz="0.0" izz="0.166667"/>
    </inertial>
  </link>

  <link name="castor_cylinder">
    <visual>
      <geometry>
        <cylinder length="0.03" radius="0.05"/>
      </geometry>
      <origin rpy="0 0 0" xyz="0 0 0"/>
    </visual>

    <collision>
      <geometry>
        <cylinder length="0.03" radius="0.05"/>
      </geometry>
      <origin rpy ="0 0 0" xyz="0 0 0"/>
    </collision>
      
    <inertial>
      <mass value="2"/>
      <inertia ixx="0.166667" ixy="0.0" ixz="0.0" iyy="0.166667" iyz="0.0" izz="0.166667"/>
    </inertial>
  </link>

  <link name="castor_ball2">
    <visual>
      <geometry>
        <sphere radius="0.05"/>
      </geometry>
      <origin rpy="0 0 0" xyz="0 0 0"/>
    </visual>
    
    <collision>
      <geometry>
        <sphere radius="0.05"/>
      </geometry>
      <origin rpy="0 0 0" xyz="0 0 0"/>
    </collision>
    
    <inertial>
      <mass value="3"/>
      <inertia ixx="0.166667" ixy="0.0" ixz="0.0" iyy="0.166667" iyz="0.0" izz="0.166667"/>
    </inertial>
  </link>
      
  <link name="castor_cylinder2">
    <visual>
      <geometry>
        <cylinder length="0.03" radius="0.05"/>
      </geometry>
      <origin rpy="0 0 0" xyz="0 0 0"/>
    </visual>
    
    <collision>
      <geometry>
        <cylinder length="0.03" radius="0.05"/>
      </geometry>
      <origin rpy ="0 0 0" xyz="0 0 0"/>
    </collision>
        
    <inertial>
      <mass value="2"/>
      <inertia ixx="0.166667" ixy="0.0" ixz="0.0" iyy="0.166667" iyz="0.0" izz="0.166667"/>
    </inertial>
  </link>
  
  <joint name="footprint_to_baselink" type="fixed">
    <parent link="base_footprint"/>
    <child link="base_link"/>
    <origin rpy ="0 0 0.010" xyz="0 0 0"/>
  </joint>

  <joint name="body_to_wheel1" type="continuous">
    <parent link="base_link"/>
    <child link="wheel1"/>
    <axis xyz="1 0 0"/>
    <origin rpy ="0 0 1.5707" xyz="0.0 -0.21 0"/>
  </joint>
  
  <joint name="body_to_wheel2" type="continuous">
    <parent link="base_link"/>
    <child link="wheel2"/>
    <axis xyz="-1 0 0"/>
    <origin rpy ="0 0 -1.5707" xyz="-0.005 0.22 0"/>
  </joint>

  <joint name="body_to_castor_cylinder" type="continuous">
    <parent link="base_link"/>
    <child link="castor_cylinder"/>
    <axis xyz="0 0 1"/>
    <origin rpy ="0 0 0" xyz="-0.37 0 0"/>
  </joint>

  <joint name="cylinder_to_castor_ball" type="continuous">
    <parent link="castor_cylinder"/>
    <child link="castor_ball"/>
    <axis xyz="0 1 0"/>
    <origin rpy ="0 0.132544 0" xyz="0 0 -0.065"/>
  </joint>

  <joint name="body_to_cam" type="fixed">
    <parent link="base_link"/>
    <child link="zed_camera"/>
    <origin rpy ="0 0 0" xyz="0.14 0.02 0.905"/>
  </joint>

  <joint name="body_to_gps" type="fixed">
    <parent link="base_link"/>
    <child link="gps_link"/>
    <origin rpy ="0 0 0" xyz="-0.26 0 0.275"/>
  </joint>

  <joint name="body_to_imu" type="fixed">
    <parent link="base_link"/>
    <child link="imu_link"/>
    <origin rpy ="0 0 0" xyz="-0.1 0 0.275"/>
  </joint>

  <joint name="body_to_castor_cylinder2" type="continuous">
    <parent link="base_link"/>
    <child link="castor_cylinder2"/>
    <axis xyz="0 0 1"/>
    <origin rpy ="0 0 0" xyz="0.37 0 -0.01"/>
  </joint>

  <joint name="cylinder_to_castor_ball2" type="continuous">
    <parent link="castor_cylinder2"/>
    <child link="castor_ball2"/>
    <axis xyz="0 1 0"/>
    <origin rpy ="0 0.132544 0" xyz="0 0 -0.065"/>
  </joint>
  
  <joint name="perp" type="fixed">
    <parent link="base_link"/>
    <child link="perpendicular"/>
    <origin rpy ="-1.5707 0 -1.5707" xyz="-0.02 0.13 0.905"/>
  </joint>

  <gazebo>
    <plugin filename="libgazebo_ros_diff_drive.so" name="differential_drive_controller">
      <ros>
        <!-- <namespace>/vnymous</namespace> -->
      </ros>

      <!-- wheels -->
      <left_joint>body_to_wheel2</left_joint>
      <right_joint>body_to_wheel1</right_joint>

      <!-- kinematics -->
      <wheel_separation>0.43</wheel_separation>
      <wheel_diameter>0.24</wheel_diameter>

      <!-- limits -->
      <max_wheel_torque>100</max_wheel_torque>
      <max_wheel_acceleration>2.5</max_wheel_acceleration>

      <!-- output -->
      <publish_odom>true</publish_odom>
      <publish_odom_tf>false</publish_odom_tf>
      <publish_wheel_tf>false</publish_wheel_tf>

      <odometry_frame>odom</odometry_frame>
      <robot_base_frame>base_footprint</robot_base_frame>
    </plugin>
  </gazebo>
  
  <gazebo>
    <plugin name="joint_states" filename="libgazebo_ros_joint_state_publisher.so">
      <ros>
        <!-- <namespace>/br</namespace> -->
        <remapping>~/out:=joint_states</remapping>
      </ros>
      <update_rate>30</update_rate>
      <joint_name>footprint_to_baselink</joint_name>
      <joint_name>body_to_wheel1</joint_name>
      <joint_name>body_to_wheel2</joint_name>
      <joint_name>body_to_cam</joint_name>
      <joint_name>body_to_gps</joint_name>
      <joint_name>body_to_castor_cylinder</joint_name>
      <joint_name>body_to_castor_cylinder2</joint_name>
      <joint_name>cylinder_to_castor_ball</joint_name>
      <joint_name>cylinder_to_castor_ball2</joint_name>
      <joint_name>body_to_perpendicular</joint_name>
    </plugin>
</gazebo>

  <!-- COLORS -->

  <gazebo reference="base_link"> 
    <material>Gazebo/BlueLaser</material>
  </gazebo>

  <gazebo reference="zed_camera"> 
    <material>Gazebo/Grey</material>
  </gazebo>

  <gazebo reference="wheel1"> 
    <material>Gazebo/Black</material>
  </gazebo>

  <gazebo reference="wheel2"> 
    <material>Gazebo/Black</material>
  </gazebo>

  <gazebo reference="castor_cylinder"> 
    <material>Gazebo/Black</material>
  </gazebo>

  <gazebo reference="castor_cylinder2"> 
    <material>Gazebo/Black</material>
  </gazebo>

  <gazebo reference="castor_ball"> 
    <material>Gazebo/Black</material>
  </gazebo>

  <gazebo reference="castor_ball2"> 
    <material>Gazebo/Black</material>
  </gazebo>
</robot> 
